<?xml version="1.0"?>
<robot name="robot_arm">

  <material name="blue">
    <color rgba="0 0 0.8 1"/>
  </material>
  <material name="black">
    <color rgba="0 0 0 1"/>
  </material>
  <material name="white">
    <color rgba="1 1 1 1"/>
  </material>

  <link name="base_link">
    <visual>
      <geometry>
        <box size="0.6 0.6 0.6"/>
      </geometry>
      <origin rpy="0 1.57075 0" xyz="0 0 0.3"/>
      <material name="blue"/>
    </visual>
    <collision>
      <geometry>
        <cylinder length="0.6" radius="0.2"/>
      </geometry>
    </collision>
    <inertial>
      <mass value="10"/>
      <inertia ixx="1.0" ixy="0.0" ixz="0.0" iyy="1.0" iyz="0.0" izz="1.0"/>
    </inertial>
  </link>

  <link name="link_1">
    <visual>
      <geometry>
        <cylinder length="0.6" radius="0.2"/>
      </geometry>
      <origin rpy="0 0 0" xyz="0 0 0.3"/>
      <material name="white"/>
    </visual>
    <collision>
      <geometry>
        <box size="0.6 0.6 0.6"/>
      </geometry>
      <origin rpy="0 1.57075 0" xyz="0 0 0.3"/>
    </collision>
    <inertial>
      <mass value="10"/>
      <inertia ixx="1.0" ixy="0.0" ixz="0.0" iyy="1.0" iyz="0.0" izz="1.0"/>
    </inertial>
  </link>
  <!--
  <joint name="base_to_right_leg" type="fixed">
    <parent link="base_link"/>
    <child link="link_1"/>
    <origin xyz="0 0 0.15"/>
  </joint>
-->

  <joint name="joint_1" type="revolute">
    <axis xyz="0 0 -1"/>
    <limit effort="1000.0" lower="-3.14" upper="3.14" velocity="0.5"/>
    <origin rpy="0 0 0" xyz="0 0 0.6"/>
    <parent link="base_link"/>
    <child link="link_1"/>
  </joint>

  <link name="link_2">
    <visual>
      <geometry>
        <box size="0.2 1.2 0.3"/>
      </geometry>
      <origin rpy="0 1.57075 0" xyz="0 0.5 0.1"/>
      <material name="black"/>
    </visual>
    <collision>
      <geometry>
        <cylinder length="0.6" radius="0.2"/>
      </geometry>
    </collision>
    <inertial>
      <mass value="10"/>
      <inertia ixx="1.0" ixy="0.0" ixz="0.0" iyy="1.0" iyz="0.0" izz="1.0"/>
    </inertial>
  </link>  

   <joint name="joint_2" type="fixed">
    <origin rpy="0 0 0" xyz="0 0 0.6"/>
    <parent link="link_1"/>
    <child link="link_2"/>
  </joint>



   <link name="link_3">
    <visual>
      <geometry>
        <cylinder length="0.8" radius="0.1"/>
      </geometry>
      <origin rpy="0 0 0" xyz="0 0 0"/>
      <material name="blue"/>
    </visual>
    <collision>
      <geometry>
        <box size="0 0 0"/>
      </geometry>
      <origin rpy="0 1.57075 0" xyz="0 0 0"/>
    </collision>
    <inertial>
      <mass value="10"/>
      <inertia ixx="1.0" ixy="0.0" ixz="0.0" iyy="1.0" iyz="0.0" izz="1.0"/>
    </inertial>
  </link>

    <joint name="joint_3" type="prismatic">
    <axis xyz="0 0 1"/>
    <parent link="link_2"/>
    <child link="link_3"/>
    <limit effort="1000.0" lower="-0.5" upper="0" velocity="0.5"/>
    <origin rpy="0 0 0" xyz="0 1 0.3"/>
  </joint>


   <link name="link_4">
    <visual>
      <geometry>
        <box size="0.2 0.2 0.2"/>
      </geometry>
      <origin rpy="0 1.57075 0" xyz="0 0 0"/>
      <material name="white"/>
    </visual>
    <collision>
      <geometry>
        <cylinder length="0.6" radius="0.2"/>
      </geometry>
    </collision>
    <inertial>
      <mass value="10"/>
      <inertia ixx="1.0" ixy="0.0" ixz="0.0" iyy="1.0" iyz="0.0" izz="1.0"/>
    </inertial>
  </link>

    <joint name="joint_4" type="continuous">
    <axis xyz="0 0 1"/>
    <!--limit effort="1000.0" lower="-3.14" upper="3.14" velocity="0.5"/-->
    <origin rpy="0 0 0" xyz="0 0 -0.5"/>
    <parent link="link_3"/>
    <child link="link_4"/>
  </joint>


</robot>